Workbook
Name AgenticDict: Dictionary!$A$2:$A$177
Name AgenticTerm: Dictionary!$F$2:$F$155
Name CommunalDict: Dictionary!$B$2:$B$103
Name CommunalTerm: Dictionary!$G$2:$G$119
Name NegativeDict: Dictionary!$D$2:$D$22
Name NeutralDict: Dictionary!$C$2:$C$42
Name NeutralTerm: Dictionary!$E$2:$E$55

Sheet Final
A1: Base_CV_ID | B1: Field | C1: Framing | D1: Cover_Letter | E1: Agentic_Count | F1: Communal_Count | G1: Neutral_Count | H1: Negative_Count | I1: Total_Words | J1: Count_Percent | K1: AC_Percent | L1: Similarity | M1: Status
A2: 1 | B2: Sales / Business Development | C2: Agentic | D2: Dear Hiring Manager, I am writing to express my strong interest in the Sales Executive position at your company. As a professional specialized in market expansion and customer management, I am eager to take full ownership of the operational responsibilities outlined for this role. In my previous position, my daily duties involved managing customer accounts, tracking regional industry metrics, and executing established sales processes to achieve the quarterly quota. I leverage standard CRM software to optimize operational data, resolve complex issues, and ensure that specific customer requirements are accurately documented. My proactive approach to communication focuses on presenting clear product presentations and delivering technical information to help stakeholders execute their purchasing action. Enclosed is my resume, which delivers additional details regarding my qualifications and specialization. I welcome the opportunity for an interview to demonstrate how my expertise will bring immediate value to your organization. Thank you for your time and consideration. Regards, [Your Name] | E2: {=SUMPRODUCT(ISNUMBER(SEARCH(AgenticDict, D2))*1)} -> 9 | F2: {=SUMPRODUCT(ISNUMBER(SEARCH(CommunalDict, D2))*1)} -> 0 | G2: {=SUMPRODUCT(ISNUMBER(SEARCH(NeutralDict, D2))*1)} -> 23 | H2: =SUMPRODUCT(ISNUMBER(SEARCH(NegativeDict, D2))*1) -> 0 | I2: =IF(LEN(TRIM(D2))=0,0,LEN(TRIM(D2))-LEN(SUBSTITUTE(TRIM(D2)," ",""))+7) -> 154 | J2: =SUM( I2 / VLOOKUP(A2, BaseUP!A:H, 8, FALSE)*100) -> 106.94444 | K2: =IF($C2="Agentic",SUM(E2/I2*100),SUM(F2/I2*100)) -> 5.8441558 | L2: [] | M2: =IF(AND(J2<=112, J2>=90, K2<=10.5, K2>=4.5, L2="[]"), "Pass", "Fail") -> Pass
A3: 1 | B3: Sales / Business Development | C3: Communal | D3: Dear Hiring Manager, I am writing to submit my application for the Sales Executive position at your company. With my collection of education and work experience in business development and customer management, I look forward to dedicating myself to fulfill the responsibilities of this role. In my previous position, my daily duties involved developing client accounts alongside the team, tracking regional industry metrics, and develop along established sales processes to contribute to the quarterly quota. I utilize standard CRM software to log operational data, address issues together, and ensure that specific client requirements are supported and documented. My collaborative approach to communication focuses on explaining clear product presentations and sharing technical information to help partner stakeholders consider their purchasing actions. Enclosed is my resume, which shares additional details regarding my qualifications and skills. I welcome the opportunity for an interview to explore how my relational skills will support your organization. Thank you for your time and consideration. Sincerely, [Your Name] | E3: {=SUMPRODUCT(ISNUMBER(SEARCH(AgenticDict, D3))*1)} -> 0 | F3: {=SUMPRODUCT(ISNUMBER(SEARCH(CommunalDict, D3))*1)} -> 8 | G3: {=SUMPRODUCT(ISNUMBER(SEARCH(NeutralDict, D3))*1)} -> 27 | H3: =SUMPRODUCT(ISNUMBER(SEARCH(NegativeDict, D3))*1) -> 0 | I3: =IF(LEN(TRIM(D3))=0,0,LEN(TRIM(D3))-LEN(SUBSTITUTE(TRIM(D3)," ",""))+7) -> 160 | J3: =SUM( I3 / VLOOKUP(A3, BaseUP!A:H, 8, FALSE)*100) -> 111.11111 | K3: =IF($C3="Agentic",SUM(E3/I3*100),SUM(F3/I3*100)) -> 5 | L3: [] | M3: =IF(AND(J3<=112, J3>=90, K3<=10.5, K3>=4.5, L3="[]"), "Pass", "Fail") -> Pass
A4: 2 | B4: Sales / Business Development | C4: Agentic | D4: Dear Hiring Manager, Please accept this application for the Business Development Specialist role currently open within your organization. I have established specialized expertise in the commercial sector, where I have strategically spent several years identifying industry growth paths and monitoring market developments. My experience includes managing customer acquisition processes, conducting systematic reviews of industry data, and maintaining direct communication across internal and external groups. In my last assignment, I took ownership of identifying alignment between our product specifications and specific customer requirements, executing an optimized workflow from initial contract discussions to final signing. I am accustomed to leveraging performance tracking software and technology to report on account status and deliver operational information to the organization. I have attached my resume for your comprehensive review. I look forward to the possibility of a follow-up contact to schedule a discussion regarding my qualifications for this position. Regards, [Your Name] | E4: {=SUMPRODUCT(ISNUMBER(SEARCH(AgenticDict, D4))*1)} -> 10 | F4: {=SUMPRODUCT(ISNUMBER(SEARCH(CommunalDict, D4))*1)} -> 0 | G4: {=SUMPRODUCT(ISNUMBER(SEARCH(NeutralDict, D4))*1)} -> 22 | H4: =SUMPRODUCT(ISNUMBER(SEARCH(NegativeDict, D4))*1) -> 0 | I4: =IF(LEN(TRIM(D4))=0,0,LEN(TRIM(D4))-LEN(SUBSTITUTE(TRIM(D4)," ",""))+7) -> 148 | J4: =SUM( I4 / VLOOKUP(A4, BaseUP!A:H, 8, FALSE)*100) -> 106.47482 | K4: =IF($C4="Agentic",SUM(E4/I4*100),SUM(F4/I4*100)) -> 6.7567568 | L4: [] | M4: =IF(AND(J4<=112, J4>=90, K4<=10.5, K4>=4.5, L4="[]"), "Pass", "Fail") -> Pass
A5: 2 | B5: Sales / Business Development | C5: Communal | D5: Dear Hiring Manager, Please accept this application for the Business Development Specialist role currently open within your organization. I have built relevant experience in the commercial sector, where I have dedicated several years identifying industry growth paths and monitoring market developments. My experience includes supporting customer acquisition processes, conducting systematic reviews of industry data, and maintaining professional communication across internal and external teams. In my last assignment, I was responsible for building alignment between our product specifications and specific client requirements, ensuring a collaborated workflow from initial contract discussions to final signing. I am accustomed to using performance tracking software and technology to connect on account status and provide helpful information to the organization. I have attached my resume for your comprehensive review. I look forward to the possibility of a follow-up contact to schedule a discussion and share my qualifications for this position. Sincerely, [Your Name] | E5: {=SUMPRODUCT(ISNUMBER(SEARCH(AgenticDict, D5))*1)} -> 2 | F5: {=SUMPRODUCT(ISNUMBER(SEARCH(CommunalDict, D5))*1)} -> 8 | G5: {=SUMPRODUCT(ISNUMBER(SEARCH(NeutralDict, D5))*1)} -> 21 | H5: =SUMPRODUCT(ISNUMBER(SEARCH(NegativeDict, D5))*1) -> 0 | I5: =IF(LEN(TRIM(D5))=0,0,LEN(TRIM(D5))-LEN(SUBSTITUTE(TRIM(D5)," ",""))+7) -> 148 | J5: =SUM( I5 / VLOOKUP(A5, BaseUP!A:H, 8, FALSE)*100) -> 106.47482 | K5: =IF($C5="Agentic",SUM(E5/I5*100),SUM(F5/I5*100)) -> 5.4054054 | L5: [] | M5: =IF(AND(J5<=112, J5>=90, K5<=10.5, K5>=4.5, L5="[]"), "Pass", "Fail") -> Pass
A6: 3 | B6: Procurement / Sourcing / Supply Chain | C6: Agentic | D6: Dear Hiring Manager, I am writing to apply for the Procurement Officer position at your company. I have driven a strategic background in supply chain activities, with specialized expertise working with vendor, contract administration, and compliance monitoring. In my previous role, I took ownership of executing standard procurement processes, including verifying vendor qualifications and tracking adherence to strict technical requirements. I consistently checked data during pricing reviews to optimize performance and ensure purchases remained within the allocated departmental budget. Additionally, I negotiated terms for commercial agreements and managed quality across all supplier products to maintain full compliance with internal operating policies. My attached resume details my formal credentials and specific experience with enterprise resource planning software. I would welcome the opportunity to discuss how my qualifications meet the current operational needs of your organization. Thank you for your time and consideration. Regards, [Your Name] | E6: {=SUMPRODUCT(ISNUMBER(SEARCH(AgenticDict, D6))*1)} -> 10 | F6: {=SUMPRODUCT(ISNUMBER(SEARCH(CommunalDict, D6))*1)} -> 0 | G6: {=SUMPRODUCT(ISNUMBER(SEARCH(NeutralDict, D6))*1)} -> 20 | H6: =SUMPRODUCT(ISNUMBER(SEARCH(NegativeDict, D6))*1) -> 0 | I6: =IF(LEN(TRIM(D6))=0,0,LEN(TRIM(D6))-LEN(SUBSTITUTE(TRIM(D6)," ",""))+7) -> 144 | J6: =SUM( I6 / VLOOKUP(A6, BaseUP!A:H, 8, FALSE)*100) -> 109.92366 | K6: =IF($C6="Agentic",SUM(E6/I6*100),SUM(F6/I6*100)) -> 6.9444444 | L6: [] | M6: =IF(AND(J6<=112, J6>=90, K6<=10.5, K6>=4.5, L6="[]"), "Pass", "Fail") -> Pass
A7: 3 | B7: Procurement / Sourcing / Supply Chain | C7: Communal | D7: Dear Hiring Manager, I am writing to apply for the Procurement Officer position at your company. I have built a background in supply chain activities, with dedicated experience working with vendor, contract administration, and compliance monitoring. In my previous role, I was responsible for working standard procurement processes, including verifying vendor qualifications and supporting adherence to technical requirements. I regularly checked data during pricing reviews alongside internal teams to ensure purchases remained within the collective budget. Additionally, I collaborated to reach an agreement for commercial contracts and built trust across all supplier products to maintain full compliance with internal operating policies. My attached resume details my formal credentials and specific experience with enterprise resource planning software. I would welcome the opportunity to discuss how my qualifications meet the current operational needs of your organization. Thank you for your time and consideration. Sincerely, [Your Name] | E7: {=SUMPRODUCT(ISNUMBER(SEARCH(AgenticDict, D7))*1)} -> 0 | F7: {=SUMPRODUCT(ISNUMBER(SEARCH(CommunalDict, D7))*1)} -> 7 | G7: {=SUMPRODUCT(ISNUMBER(SEARCH(NeutralDict, D7))*1)} -> 20 | H7: =SUMPRODUCT(ISNUMBER(SEARCH(NegativeDict, D7))*1) -> 0 | I7: =IF(LEN(TRIM(D7))=0,0,LEN(TRIM(D7))-LEN(SUBSTITUTE(TRIM(D7)," ",""))+7) -> 144 | J7: =SUM( I7 / VLOOKUP(A7, BaseUP!A:H, 8, FALSE)*100) -> 109.92366 | K7: =IF($C7="Agentic",SUM(E7/I7*100),SUM(F7/I7*100)) -> 4.8611111 | L7: [] | M7: =IF(AND(J7<=112, J7>=90, K7<=10.5, K7>=4.5, L7="[]"), "Pass", "Fail") -> Pass
A8: 4 | B8: Procurement / Sourcing / Supply Chain | C8: Agentic | D8: Dear Hiring Manager, This letter is in reference to the Logistics Coordinator role currently available within your organization. My background includes strong technical training and experience in supply chain tracking, logistics, and inventory management. My professional focus is on executing high-caliber, driven workflow processes. In my last position, I managed inventory levels, optimized performance in shipment schedules, and coordinated tracking data using in-house logistics software. Whenever discrepancies arose, I utilized my problem-solving skills by tracking the variance back to its source. I executed tasks with others from warehouse operations and transportation to ensure that physical stock levels aligned exactly with system requirements. My qualifications are outlined in detail in the attached resume. Please feel free to contact me via the information provided to schedule a discussion regarding this position. Thank you for your review and consideration. Regards, [Your Name] | E8: {=SUMPRODUCT(ISNUMBER(SEARCH(AgenticDict, D8))*1)} -> 7 | F8: {=SUMPRODUCT(ISNUMBER(SEARCH(CommunalDict, D8))*1)} -> 0 | G8: {=SUMPRODUCT(ISNUMBER(SEARCH(NeutralDict, D8))*1)} -> 21 | H8: =SUMPRODUCT(ISNUMBER(SEARCH(NegativeDict, D8))*1) -> 0 | I8: =IF(LEN(TRIM(D8))=0,0,LEN(TRIM(D8))-LEN(SUBSTITUTE(TRIM(D8)," ",""))+7) -> 139 | J8: =SUM( I8 / VLOOKUP(A8, BaseUP!A:H, 8, FALSE)*100) -> 109.44882 | K8: =IF($C8="Agentic",SUM(E8/I8*100),SUM(F8/I8*100)) -> 5.0359712 | L8: [] | M8: =IF(AND(J8<=112, J8>=90, K8<=10.5, K8>=4.5, L8="[]"), "Pass", "Fail") -> Pass
A9: 4 | B9: Procurement / Sourcing / Supply Chain | C9: Communal | D9: Dear Hiring Manager, This letter is in reference to the Logistics Coordinator role currently available within your organization. My background includes technical training and joint experience in supply chain tracking, logistics, and inventory management. My professional focus is on maintaining stable, supportive workflow processes. In my last position, I assisted in managing inventory levels, shipment schedules, and tracking data alongside the team using in-house logistics software. Whenever discrepancies arose, I restored harmony by tracking the variance back to its source. I worked with others with a cooperative spirit from warehouse operations and transportation to ensure that physical stock levels aligned exactly with system requirements. My qualifications are outlined in detail in the attached resume. Please feel free to contact me via the information provided to schedule a discussion regarding this position. Thank you for your review and consideration. Sincerely, [Your Name] | E9: {=SUMPRODUCT(ISNUMBER(SEARCH(AgenticDict, D9))*1)} -> 1 | F9: {=SUMPRODUCT(ISNUMBER(SEARCH(CommunalDict, D9))*1)} -> 7 | G9: {=SUMPRODUCT(ISNUMBER(SEARCH(NeutralDict, D9))*1)} -> 20 | H9: =SUMPRODUCT(ISNUMBER(SEARCH(NegativeDict, D9))*1) -> 0 | I9: =IF(LEN(TRIM(D9))=0,0,LEN(TRIM(D9))-LEN(SUBSTITUTE(TRIM(D9)," ",""))+7) -> 141 | J9: =SUM( I9 / VLOOKUP(A9, BaseUP!A:H, 8, FALSE)*100) -> 111.02362 | K9: =IF($C9="Agentic",SUM(E9/I9*100),SUM(F9/I9*100)) -> 4.964539 | L9: [] | M9: =IF(AND(J9<=112, J9>=90, K9<=10.5, K9>=4.5, L9="[]"), "Pass", "Fail") -> Pass
A10: 5 | B10: Project Management / Programme Management | C10: Agentic | D10: Dear Hiring Manager, I am writing to express my interest in the Project Manager position at your company. I possess experience in corporate administration, where my focus is on tracking project deliverables, budgets, and maintaining project timelines. Throughout my career, I have effectively managed a project workflow from initial scope definition through to completion based on documented requirements. My daily tasks include executing main project schedules and tracking resource allocation against the budget using tracking software. In my previous assignments, I directed technical personnel and optimized performance across all milestones by adhering strictly to formal testing and verification compliance frameworks. My background includes specialized certification in standard project methodologies. Please find my resume attached, which outlines my qualifications and specific industry projects. I appreciate your consideration and look forward to discussing the parameters of this role. Regards, [Your Name] | E10: {=SUMPRODUCT(ISNUMBER(SEARCH(AgenticDict, D10))*1)} -> 7 | F10: {=SUMPRODUCT(ISNUMBER(SEARCH(CommunalDict, D10))*1)} -> 0 | G10: {=SUMPRODUCT(ISNUMBER(SEARCH(NeutralDict, D10))*1)} -> 18 | H10: =SUMPRODUCT(ISNUMBER(SEARCH(NegativeDict, D10))*1) -> 0 | I10: =IF(LEN(TRIM(D10))=0,0,LEN(TRIM(D10))-LEN(SUBSTITUTE(TRIM(D10)," ",""))+7) -> 140 | J10: =SUM( I10 / VLOOKUP(A10, BaseUP!A:H, 8, FALSE)*100) -> 101.44928 | K10: =IF($C10="Agentic",SUM(E10/I10*100),SUM(F10/I10*100)) -> 5 | L10: [] | M10: =IF(AND(J10<=112, J10>=90, K10<=10.5, K10>=4.5, L10="[]"), "Pass", "Fail") -> Pass
A11: 5 | B11: Project Management / Programme Management | C11: Communal | D11: Dear Hiring Manager, I am writing to express my interest in the Project Manager position at your company. I possess cooperative experience in corporate administration, where my shared focus is on tracking project deliverables, budgets, and maintaining project timelines. Throughout my career, I have successfully looked after a project workflow as a collaborative effort from initial scope definition through to completion based on documented requirements. My daily tasks include updating main project schedules and tracking resource allocation alongside the team using tracking software. In my previous assignments, I led a cohesive team of technical personnel and ensured supportive work across all milestones by adhering strictly to formal testing and verification compliance frameworks. My background includes specific certification in standard project methodologies. Please find my resume attached, which outlines my contribution, qualifications and specific industry projects. I sincerely appreciate your consideration and look forward to discussing the parameters of this role. Sincerely, [Your Name] | E11: {=SUMPRODUCT(ISNUMBER(SEARCH(AgenticDict, D11))*1)} -> 0 | F11: {=SUMPRODUCT(ISNUMBER(SEARCH(CommunalDict, D11))*1)} -> 8 | G11: {=SUMPRODUCT(ISNUMBER(SEARCH(NeutralDict, D11))*1)} -> 18 | H11: =SUMPRODUCT(ISNUMBER(SEARCH(NegativeDict, D11))*1) -> 0 | I11: =IF(LEN(TRIM(D11))=0,0,LEN(TRIM(D11))-LEN(SUBSTITUTE(TRIM(D11)," ",""))+7) -> 154 | J11: =SUM( I11 / VLOOKUP(A11, BaseUP!A:H, 8, FALSE)*100) -> 111.5942 | K11: =IF($C11="Agentic",SUM(E11/I11*100),SUM(F11/I11*100)) -> 5.1948052 | L11: [] | M11: =IF(AND(J11<=112, J11>=90, K11<=10.5, K11>=4.5, L11="[]"), "Pass", "Fail") -> Pass
A12: 6 | B12: Project Management / Programme Management | C12: Agentic | D12: Dear Hiring Manager, Please accept my application for the Programme Coordinator role within your organization. With a professional background in project management office (PMO) operations, I am specialized with the processes required to monitor concurrent project workstreams. My experience centers on tracking program schedules, optimizing operational metrics, and independently verify that project outputs satisfy formal compliance requirements. I proactively direct data analysis to generate accurate status reports for the organization. In this role, I executed tasks with others across different project departments and communicated insights regarding standard operating procedures to maintain consistency in scheduling and documentation formats. My resume is attached for your comprehensive review. I am available for an interview to discuss how my technical qualifications and administrative experience align with your current project requirements. Thank you for your consideration. Regards, [Your Name] | E12: {=SUMPRODUCT(ISNUMBER(SEARCH(AgenticDict, D12))*1)} -> 7 | F12: {=SUMPRODUCT(ISNUMBER(SEARCH(CommunalDict, D12))*1)} -> 1 | G12: {=SUMPRODUCT(ISNUMBER(SEARCH(NeutralDict, D12))*1)} -> 18 | H12: =SUMPRODUCT(ISNUMBER(SEARCH(NegativeDict, D12))*1) -> 0 | I12: =IF(LEN(TRIM(D12))=0,0,LEN(TRIM(D12))-LEN(SUBSTITUTE(TRIM(D12)," ",""))+7) -> 134 | J12: =SUM( I12 / VLOOKUP(A12, BaseUP!A:H, 8, FALSE)*100) -> 107.2 | K12: =IF($C12="Agentic",SUM(E12/I12*100),SUM(F12/I12*100)) -> 5.2238806 | L12: [] | M12: =IF(AND(J12<=112, J12>=90, K12<=10.5, K12>=4.5, L12="[]"), "Pass", "Fail") -> Pass
A13: 6 | B13: Project Management / Programme Management | C13: Communal | D13: Dear Hiring Manager, Please accept my application for the Programme Coordinator role within your organization. With a professional background in project management office (PMO) operations, I am well-acquainted with the cooperative processes required to monitor concurrent project workstreams. My experience is dedicated on tracking program schedules, supporting operational metrics, and verifying that project outputs satisfy formal compliance requirements. I routinely assisted with data to generate accurate status reports for the organization. In this role, I worked alongside the team across different project departments and communicated information regarding standard operating procedures to maintain consistency in scheduling and documentation formats. My resume is attached for your comprehensive review. I am available for an interview to share how my technical qualifications and administrative experience align with your current project requirements. Thank you for your consideration. Sincerely, [Your Name] | E13: {=SUMPRODUCT(ISNUMBER(SEARCH(AgenticDict, D13))*1)} -> 0 | F13: {=SUMPRODUCT(ISNUMBER(SEARCH(CommunalDict, D13))*1)} -> 7 | G13: {=SUMPRODUCT(ISNUMBER(SEARCH(NeutralDict, D13))*1)} -> 19 | H13: =SUMPRODUCT(ISNUMBER(SEARCH(NegativeDict, D13))*1) -> 0 | I13: =IF(LEN(TRIM(D13))=0,0,LEN(TRIM(D13))-LEN(SUBSTITUTE(TRIM(D13)," ",""))+7) -> 135 | J13: =SUM( I13 / VLOOKUP(A13, BaseUP!A:H, 8, FALSE)*100) -> 108 | K13: =IF($C13="Agentic",SUM(E13/I13*100),SUM(F13/I13*100)) -> 5.1851852 | L13: [] | M13: =IF(AND(J13<=112, J13>=90, K13<=10.5, K13>=4.5, L13="[]"), "Pass", "Fail") -> Pass
... A181: 90 | B181: Project Management / Programme Management | C181: Communal | D181: Dear Hiring Manager, I am writing to express interest in the Project Management position at [Company]. My professional background aligns with the requirements stated in the job description, and I am submitting my application for your consideration. My experience includes management of projects within [Location]. In previous roles, I collaborate on project timelines, maintained documentation, and tracked progress against collective goals. I have managed budgets and resources to ensure the contribution of assigned tasks through a cooperative approach. My skill set includes the use of project management software, data analysis, and technical reporting. I possess experience in risk assessment and assisting in the joint coordination of project phases. These skills allow for the mutual trust of schedules and the shared management of project documentation. I am available for an interview to discuss how my background meets the needs of [Company]. Please contact me via the information provided on my resume to arrange a time for further discussion. Thank you for your time and consideration of this application. Regards, [Your Name] | E181: {=SUMPRODUCT(ISNUMBER(SEARCH(AgenticDict, D181))*1)} -> 3 | F181: {=SUMPRODUCT(ISNUMBER(SEARCH(CommunalDict, D181))*1)} -> 11 | G181: {=SUMPRODUCT(ISNUMBER(SEARCH(NeutralDict, D181))*1)} -> 16 | H181: =SUMPRODUCT(ISNUMBER(SEARCH(NegativeDict, D181))*1) -> 0 | I181: =IF(LEN(TRIM(D181))=0,0,LEN(TRIM(D181))-LEN(SUBSTITUTE(TRIM(D181)," ",""))+7) -> 170 | J181: =SUM( I181 / VLOOKUP(A181, BaseUP!A:H, 8, FALSE)*100) -> 106.25 | K181: =IF($C181="Agentic",SUM(E181/I181*100),SUM(F181/I181*100)) -> 6.4705882 | L181: [] | M181: =IF(AND(J181<=112, J181>=90, K181<=10.5, K181>=4.5, L181="[]"), "Pass", "Fail") -> Pass

Sheet FinalBackup
A1: Base_CV_ID | B1: Field | C1: Framing | D1: Cover_Letter | E1: Agentic_Count | F1: Communal_Count | G1: Neutral_Count | H1: Negative_Count | I1: Total_Words | J1: Count_Percent | K1: AC_Percent | L1: Similarity | M1: Status
A2: 1 | B2: Sales / Business Development | C2: Agentic | D2: Dear Hiring Manager, I am writing to express my strong interest in the Sales Executive position at your company. As a professional specialized in market expansion and customer management, I am eager to take full ownership of the operational responsibilities outlined for this role. In my previous position, my daily duties involved managing customer accounts, tracking regional industry metrics, and executing established sales processes to achieve the quarterly quota. I leverage standard CRM software to optimize operational data, resolve complex issues, and ensure that specific customer requirements are accurately documented. My proactive approach to communication focuses on presenting clear product presentations and delivering technical information to help stakeholders execute their purchasing action. Enclosed is my resume, which delivers additional details regarding my qualifications and specialization. I welcome the opportunity for an interview to demonstrate how my expertise will bring immediate value to your organization. Thank you for your time and consideration. Regards, [Your Name] | E2: {=SUMPRODUCT(ISNUMBER(SEARCH(AgenticDict, D2))*1)} -> 9 | F2: {=SUMPRODUCT(ISNUMBER(SEARCH(CommunalDict, D2))*1)} -> 0 | G2: {=SUMPRODUCT(ISNUMBER(SEARCH(NeutralDict, D2))*1)} -> 23 | H2: =SUMPRODUCT(ISNUMBER(SEARCH(NegativeDict, D2))*1) -> 0 | I2: =IF(LEN(TRIM(D2))=0,0,LEN(TRIM(D2))-LEN(SUBSTITUTE(TRIM(D2)," ",""))+7) -> 154 | J2: =SUM( I2 / VLOOKUP(A2, BaseUP!A:H, 8, FALSE)*100) -> 106.94444 | K2: =IF($C2="Agentic",SUM(E2/I2*100),SUM(F2/I2*100)) -> 5.8441558 | L2: [] | M2: =IF(AND(J2<=112, J2>=90, K2<=10.5, K2>=4.5, L2="[]"), "Pass", "Fail") -> Pass
A3: 1 | B3: Sales / Business Development | C3: Communal | D3: Dear Hiring Manager, I am writing to submit my application for the Sales Executive position at your company. With my collection of education and work experience in business development and customer management, I look forward to dedicating myself to fulfill the responsibilities of this role. In my previous position, my daily duties involved developing client accounts alongside the team, tracking regional industry metrics, and develop along established sales processes to contribute to the quarterly quota. I utilize standard CRM software to log operational data, address issues together, and ensure that specific client requirements are supported and documented. My collaborative approach to communication focuses on explaining clear product presentations and sharing technical information to help partner stakeholders consider their purchasing actions. Enclosed is my resume, which shares additional details regarding my qualifications and skills. I welcome the opportunity for an interview to explore how my relational skills will support your organization. Thank you for your time and consideration. Sincerely, [Your Name] | E3: {=SUMPRODUCT(ISNUMBER(SEARCH(AgenticDict, D3))*1)} -> 0 | F3: {=SUMPRODUCT(ISNUMBER(SEARCH(CommunalDict, D3))*1)} -> 8 | G3: {=SUMPRODUCT(ISNUMBER(SEARCH(NeutralDict, D3))*1)} -> 27 | H3: =SUMPRODUCT(ISNUMBER(SEARCH(NegativeDict, D3))*1) -> 0 | I3: =IF(LEN(TRIM(D3))=0,0,LEN(TRIM(D3))-LEN(SUBSTITUTE(TRIM(D3)," ",""))+7) -> 160 | J3: =SUM( I3 / VLOOKUP(A3, BaseUP!A:H, 8, FALSE)*100) -> 111.11111 | K3: =IF($C3="Agentic",SUM(E3/I3*100),SUM(F3/I3*100)) -> 5 | L3: [] | M3: =IF(AND(J3<=112, J3>=90, K3<=10.5, K3>=4.5, L3="[]"), "Pass", "Fail") -> Pass
A4: 2 | B4: Sales / Business Development | C4: Agentic | D4: Dear Hiring Manager, Please accept this application for the Business Development Specialist role currently open within your organization. I have established specialized expertise in the commercial sector, where I have strategically spent several years identifying industry growth paths and monitoring market developments. My experience includes managing customer acquisition processes, conducting systematic reviews of industry data, and maintaining direct communication across internal and external groups. In my last assignment, I took ownership of identifying alignment between our product specifications and specific customer requirements, executing an optimized workflow from initial contract discussions to final signing. I am accustomed to leveraging performance tracking software and technology to report on account status and deliver operational information to the organization. I have attached my resume for your comprehensive review. I look forward to the possibility of a follow-up contact to schedule a discussion regarding my qualifications for this position. Regards, [Your Name] | E4: {=SUMPRODUCT(ISNUMBER(SEARCH(AgenticDict, D4))*1)} -> 10 | F4: {=SUMPRODUCT(ISNUMBER(SEARCH(CommunalDict, D4))*1)} -> 0 | G4: {=SUMPRODUCT(ISNUMBER(SEARCH(NeutralDict, D4))*1)} -> 22 | H4: =SUMPRODUCT(ISNUMBER(SEARCH(NegativeDict, D4))*1) -> 0 | I4: =IF(LEN(TRIM(D4))=0,0,LEN(TRIM(D4))-LEN(SUBSTITUTE(TRIM(D4)," ",""))+7) -> 148 | J4: =SUM( I4 / VLOOKUP(A4, BaseUP!A:H, 8, FALSE)*100) -> 106.47482 | K4: =IF($C4="Agentic",SUM(E4/I4*100),SUM(F4/I4*100)) -> 6.7567568 | L4: [] | M4: =IF(AND(J4<=112, J4>=90, K4<=10.5, K4>=4.5, L4="[]"), "Pass", "Fail") -> Pass
A5: 2 | B5: Sales / Business Development | C5: Communal | D5: Dear Hiring Manager, Please accept this application for the Business Development Specialist role currently open within your organization. I have built relevant experience in the commercial sector, where I have dedicated several years identifying industry growth paths and monitoring market developments. My experience includes supporting customer acquisition processes, conducting systematic reviews of industry data, and maintaining professional communication across internal and external teams. In my last assignment, I was responsible for building alignment between our product specifications and specific client requirements, ensuring a collaborated workflow from initial contract discussions to final signing. I am accustomed to using performance tracking software and technology to connect on account status and provide helpful information to the organization. I have attached my resume for your comprehensive review. I look forward to the possibility of a follow-up contact to schedule a discussion and share my qualifications for this position. Sincerely, [Your Name] | E5: {=SUMPRODUCT(ISNUMBER(SEARCH(AgenticDict, D5))*1)} -> 2 | F5: {=SUMPRODUCT(ISNUMBER(SEARCH(CommunalDict, D5))*1)} -> 8 | G5: {=SUMPRODUCT(ISNUMBER(SEARCH(NeutralDict, D5))*1)} -> 21 | H5: =SUMPRODUCT(ISNUMBER(SEARCH(NegativeDict, D5))*1) -> 0 | I5: =IF(LEN(TRIM(D5))=0,0,LEN(TRIM(D5))-LEN(SUBSTITUTE(TRIM(D5)," ",""))+7) -> 148 | J5: =SUM( I5 / VLOOKUP(A5, BaseUP!A:H, 8, FALSE)*100) -> 106.47482 | K5: =IF($C5="Agentic",SUM(E5/I5*100),SUM(F5/I5*100)) -> 5.4054054 | L5: [] | M5: =IF(AND(J5<=112, J5>=90, K5<=10.5, K5>=4.5, L5="[]"), "Pass", "Fail") -> Pass
A6: 3 | B6: Procurement / Sourcing / Supply Chain | C6: Agentic | D6: Dear Hiring Manager, I am writing to apply for the Procurement Officer position at your company. I have driven a strategic background in supply chain activities, with specialized expertise working with vendor, contract administration, and compliance monitoring. In my previous role, I took ownership of executing standard procurement processes, including verifying vendor qualifications and tracking adherence to strict technical requirements. I consistently checked data during pricing reviews to optimize performance and ensure purchases remained within the allocated departmental budget. Additionally, I negotiated terms for commercial agreements and managed quality across all supplier products to maintain full compliance with internal operating policies. My attached resume details my formal credentials and specific experience with enterprise resource planning software. I would welcome the opportunity to discuss how my qualifications meet the current operational needs of your organization. Thank you for your time and consideration. Regards, [Your Name] | E6: {=SUMPRODUCT(ISNUMBER(SEARCH(AgenticDict, D6))*1)} -> 10 | F6: {=SUMPRODUCT(ISNUMBER(SEARCH(CommunalDict, D6))*1)} -> 0 | G6: {=SUMPRODUCT(ISNUMBER(SEARCH(NeutralDict, D6))*1)} -> 20 | H6: =SUMPRODUCT(ISNUMBER(SEARCH(NegativeDict, D6))*1) -> 0 | I6: =IF(LEN(TRIM(D6))=0,0,LEN(TRIM(D6))-LEN(SUBSTITUTE(TRIM(D6)," ",""))+7) -> 144 | J6: =SUM( I6 / VLOOKUP(A6, BaseUP!A:H, 8, FALSE)*100) -> 109.92366 | K6: =IF($C6="Agentic",SUM(E6/I6*100),SUM(F6/I6*100)) -> 6.9444444 | L6: [] | M6: =IF(AND(J6<=112, J6>=90, K6<=10.5, K6>=4.5, L6="[]"), "Pass", "Fail") -> Pass
A7: 3 | B7: Procurement / Sourcing / Supply Chain | C7: Communal | D7: Dear Hiring Manager, I am writing to apply for the Procurement Officer position at your company. I have built a background in supply chain activities, with dedicated experience working with vendor, contract administration, and compliance monitoring. In my previous role, I was responsible for working standard procurement processes, including verifying vendor qualifications and supporting adherence to technical requirements. I regularly checked data during pricing reviews alongside internal teams to ensure purchases remained within the collective budget. Additionally, I collaborated to reach an agreement for commercial contracts and built trust across all supplier products to maintain full compliance with internal operating policies. My attached resume details my formal credentials and specific experience with enterprise resource planning software. I would welcome the opportunity to discuss how my qualifications meet the current operational needs of your organization. Thank you for your time and consideration. Sincerely, [Your Name] | E7: {=SUMPRODUCT(ISNUMBER(SEARCH(AgenticDict, D7))*1)} -> 0 | F7: {=SUMPRODUCT(ISNUMBER(SEARCH(CommunalDict, D7))*1)} -> 7 | G7: {=SUMPRODUCT(ISNUMBER(SEARCH(NeutralDict, D7))*1)} -> 20 | H7: =SUMPRODUCT(ISNUMBER(SEARCH(NegativeDict, D7))*1) -> 0 | I7: =IF(LEN(TRIM(D7))=0,0,LEN(TRIM(D7))-LEN(SUBSTITUTE(TRIM(D7)," ",""))+7) -> 144 | J7: =SUM( I7 / VLOOKUP(A7, BaseUP!A:H, 8, FALSE)*100) -> 109.92366 | K7: =IF($C7="Agentic",SUM(E7/I7*100),SUM(F7/I7*100)) -> 4.8611111 | L7: [] | M7: =IF(AND(J7<=112, J7>=90, K7<=10.5, K7>=4.5, L7="[]"), "Pass", "Fail") -> Pass
A8: 4 | B8: Procurement / Sourcing / Supply Chain | C8: Agentic | D8: Dear Hiring Manager, This letter is in reference to the Logistics Coordinator role currently available within your organization. My background includes strong technical training and experience in supply chain tracking, logistics, and inventory management. My professional focus is on executing high-caliber, driven workflow processes. In my last position, I managed inventory levels, optimized performance in shipment schedules, and coordinated tracking data using in-house logistics software. Whenever discrepancies arose, I utilized my problem-solving skills by tracking the variance back to its source. I executed tasks with others from warehouse operations and transportation to ensure that physical stock levels aligned exactly with system requirements. My qualifications are outlined in detail in the attached resume. Please feel free to contact me via the information provided to schedule a discussion regarding this position. Thank you for your review and consideration. Regards, [Your Name] | E8: {=SUMPRODUCT(ISNUMBER(SEARCH(AgenticDict, D8))*1)} -> 7 | F8: {=SUMPRODUCT(ISNUMBER(SEARCH(CommunalDict, D8))*1)} -> 0 | G8: {=SUMPRODUCT(ISNUMBER(SEARCH(NeutralDict, D8))*1)} -> 21 | H8: =SUMPRODUCT(ISNUMBER(SEARCH(NegativeDict, D8))*1) -> 0 | I8: =IF(LEN(TRIM(D8))=0,0,LEN(TRIM(D8))-LEN(SUBSTITUTE(TRIM(D8)," ",""))+7) -> 139 | J8: =SUM( I8 / VLOOKUP(A8, BaseUP!A:H, 8, FALSE)*100) -> 109.44882 | K8: =IF($C8="Agentic",SUM(E8/I8*100),SUM(F8/I8*100)) -> 5.0359712 | L8: [] | M8: =IF(AND(J8<=112, J8>=90, K8<=10.5, K8>=4.5, L8="[]"), "Pass", "Fail") -> Pass
A9: 4 | B9: Procurement / Sourcing / Supply Chain | C9: Communal | D9: Dear Hiring Manager, This letter is in reference to the Logistics Coordinator role currently available within your organization. My background includes technical training and joint experience in supply chain tracking, logistics, and inventory management. My professional focus is on maintaining stable, supportive workflow processes. In my last position, I assisted in managing inventory levels, shipment schedules, and tracking data alongside the team using in-house logistics software. Whenever discrepancies arose, I restored harmony by tracking the variance back to its source. I worked with others with a cooperative spirit from warehouse operations and transportation to ensure that physical stock levels aligned exactly with system requirements. My qualifications are outlined in detail in the attached resume. Please feel free to contact me via the information provided to schedule a discussion regarding this position. Thank you for your review and consideration. Sincerely, [Your Name] | E9: {=SUMPRODUCT(ISNUMBER(SEARCH(AgenticDict, D9))*1)} -> 1 | F9: {=SUMPRODUCT(ISNUMBER(SEARCH(CommunalDict, D9))*1)} -> 7 | G9: {=SUMPRODUCT(ISNUMBER(SEARCH(NeutralDict, D9))*1)} -> 20 | H9: =SUMPRODUCT(ISNUMBER(SEARCH(NegativeDict, D9))*1) -> 0 | I9: =IF(LEN(TRIM(D9))=0,0,LEN(TRIM(D9))-LEN(SUBSTITUTE(TRIM(D9)," ",""))+7) -> 141 | J9: =SUM( I9 / VLOOKUP(A9, BaseUP!A:H, 8, FALSE)*100) -> 111.02362 | K9: =IF($C9="Agentic",SUM(E9/I9*100),SUM(F9/I9*100)) -> 4.964539 | L9: [] | M9: =IF(AND(J9<=112, J9>=90, K9<=10.5, K9>=4.5, L9="[]"), "Pass", "Fail") -> Pass
A10: 5 | B10: Project Management / Programme Management | C10: Agentic | D10: Dear Hiring Manager, I am writing to express my interest in the Project Manager position at your company. I possess experience in corporate administration, where my focus is on tracking project deliverables, budgets, and maintaining project timelines. Throughout my career, I have effectively managed a project workflow from initial scope definition through to completion based on documented requirements. My daily tasks include executing main project schedules and tracking resource allocation against the budget using tracking software. In my previous assignments, I directed technical personnel and optimized performance across all milestones by adhering strictly to formal testing and verification compliance frameworks. My background includes specialized certification in standard project methodologies. Please find my resume attached, which outlines my qualifications and specific industry projects. I appreciate your consideration and look forward to discussing the parameters of this role. Regards, [Your Name] | E10: {=SUMPRODUCT(ISNUMBER(SEARCH(AgenticDict, D10))*1)} -> 7 | F10: {=SUMPRODUCT(ISNUMBER(SEARCH(CommunalDict, D10))*1)} -> 0 | G10: {=SUMPRODUCT(ISNUMBER(SEARCH(NeutralDict, D10))*1)} -> 18 | H10: =SUMPRODUCT(ISNUMBER(SEARCH(NegativeDict, D10))*1) -> 0 | I10: =IF(LEN(TRIM(D10))=0,0,LEN(TRIM(D10))-LEN(SUBSTITUTE(TRIM(D10)," ",""))+7) -> 140 | J10: =SUM( I10 / VLOOKUP(A10, BaseUP!A:H, 8, FALSE)*100) -> 101.44928 | K10: =IF($C10="Agentic",SUM(E10/I10*100),SUM(F10/I10*100)) -> 5 | L10: [] | M10: =IF(AND(J10<=112, J10>=90, K10<=10.5, K10>=4.5, L10="[]"), "Pass", "Fail") -> Pass
A11: 5 | B11: Project Management / Programme Management | C11: Communal | D11: Dear Hiring Manager, I am writing to express my interest in the Project Manager position at your company. I possess cooperative experience in corporate administration, where my shared focus is on tracking project deliverables, budgets, and maintaining project timelines. Throughout my career, I have successfully looked after a project workflow as a collaborative effort from initial scope definition through to completion based on documented requirements. My daily tasks include updating main project schedules and tracking resource allocation alongside the team using tracking software. In my previous assignments, I led a cohesive team of technical personnel and ensured supportive work across all milestones by adhering strictly to formal testing and verification compliance frameworks. My background includes specific certification in standard project methodologies. Please find my resume attached, which outlines my contribution, qualifications and specific industry projects. I sincerely appreciate your consideration and look forward to discussing the parameters of this role. Sincerely, [Your Name] | E11: {=SUMPRODUCT(ISNUMBER(SEARCH(AgenticDict, D11))*1)} -> 0 | F11: {=SUMPRODUCT(ISNUMBER(SEARCH(CommunalDict, D11))*1)} -> 8 | G11: {=SUMPRODUCT(ISNUMBER(SEARCH(NeutralDict, D11))*1)} -> 18 | H11: =SUMPRODUCT(ISNUMBER(SEARCH(NegativeDict, D11))*1) -> 0 | I11: =IF(LEN(TRIM(D11))=0,0,LEN(TRIM(D11))-LEN(SUBSTITUTE(TRIM(D11)," ",""))+7) -> 154 | J11: =SUM( I11 / VLOOKUP(A11, BaseUP!A:H, 8, FALSE)*100) -> 111.5942 | K11: =IF($C11="Agentic",SUM(E11/I11*100),SUM(F11/I11*100)) -> 5.1948052 | L11: [] | M11: =IF(AND(J11<=112, J11>=90, K11<=10.5, K11>=4.5, L11="[]"), "Pass", "Fail") -> Pass
A12: 6 | B12: Project Management / Programme Management | C12: Agentic | D12: Dear Hiring Manager, Please accept my application for the Programme Coordinator role within your organization. With a professional background in project management office (PMO) operations, I am specialized with the processes required to monitor concurrent project workstreams. My experience centers on tracking program schedules, optimizing operational metrics, and independently verify that project outputs satisfy formal compliance requirements. I proactively direct data analysis to generate accurate status reports for the organization. In this role, I executed tasks with others across different project departments and communicated insights regarding standard operating procedures to maintain consistency in scheduling and documentation formats. My resume is attached for your comprehensive review. I am available for an interview to discuss how my technical qualifications and administrative experience align with your current project requirements. Thank you for your consideration. Regards, [Your Name] | E12: {=SUMPRODUCT(ISNUMBER(SEARCH(AgenticDict, D12))*1)} -> 7 | F12: {=SUMPRODUCT(ISNUMBER(SEARCH(CommunalDict, D12))*1)} -> 1 | G12: {=SUMPRODUCT(ISNUMBER(SEARCH(NeutralDict, D12))*1)} -> 18 | H12: =SUMPRODUCT(ISNUMBER(SEARCH(NegativeDict, D12))*1) -> 0 | I12: =IF(LEN(TRIM(D12))=0,0,LEN(TRIM(D12))-LEN(SUBSTITUTE(TRIM(D12)," ",""))+7) -> 134 | J12: =SUM( I12 / VLOOKUP(A12, BaseUP!A:H, 8, FALSE)*100) -> 107.2 | K12: =IF($C12="Agentic",SUM(E12/I12*100),SUM(F12/I12*100)) -> 5.2238806 | L12: [] | M12: =IF(AND(J12<=112, J12>=90, K12<=10.5, K12>=4.5, L12="[]"), "Pass", "Fail") -> Pass
A13: 6 | B13: Project Management / Programme Management | C13: Communal | D13: Dear Hiring Manager, Please accept my application for the Programme Coordinator role within your organization. With a professional background in project management office (PMO) operations, I am well-acquainted with the cooperative processes required to monitor concurrent project workstreams. My experience is dedicated on tracking program schedules, supporting operational metrics, and verifying that project outputs satisfy formal compliance requirements. I routinely assisted with data to generate accurate status reports for the organization. In this role, I worked alongside the team across different project departments and communicated information regarding standard operating procedures to maintain consistency in scheduling and documentation formats. My resume is attached for your comprehensive review. I am available for an interview to share how my technical qualifications and administrative experience align with your current project requirements. Thank you for your consideration. Sincerely, [Your Name] | E13: {=SUMPRODUCT(ISNUMBER(SEARCH(AgenticDict, D13))*1)} -> 0 | F13: {=SUMPRODUCT(ISNUMBER(SEARCH(CommunalDict, D13))*1)} -> 7 | G13: {=SUMPRODUCT(ISNUMBER(SEARCH(NeutralDict, D13))*1)} -> 19 | H13: =SUMPRODUCT(ISNUMBER(SEARCH(NegativeDict, D13))*1) -> 0 | I13: =IF(LEN(TRIM(D13))=0,0,LEN(TRIM(D13))-LEN(SUBSTITUTE(TRIM(D13)," ",""))+7) -> 135 | J13: =SUM( I13 / VLOOKUP(A13, BaseUP!A:H, 8, FALSE)*100) -> 108 | K13: =IF($C13="Agentic",SUM(E13/I13*100),SUM(F13/I13*100)) -> 5.1851852 | L13: [] | M13: =IF(AND(J13<=112, J13>=90, K13<=10.5, K13>=4.5, L13="[]"), "Pass", "Fail") -> Pass
... A181: 90 | B181: Project Management / Programme Management | C181: Communal | D181: Dear Hiring Manager, I am writing to express interest in the Project Management position at [Company]. My professional background aligns with the requirements stated in the job description, and I am submitting my application for your consideration. My experience includes management of projects within [Location]. In previous roles, I collaborate on project timelines, maintained documentation, and tracked progress against collective goals. I have managed budgets and resources to ensure the contribution of assigned tasks through a cooperative approach. My skill set includes the use of project management software, data analysis, and technical reporting. I possess experience in risk assessment and assisting in the joint coordination of project phases. These skills allow for the mutual trust of schedules and the shared management of project documentation. I am available for an interview to discuss how my background meets the needs of [Company]. Please contact me via the information provided on my resume to arrange a time for further discussion. Thank you for your time and consideration of this application. Regards, [Your Name] | E181: {=SUMPRODUCT(ISNUMBER(SEARCH(AgenticDict, D181))*1)} -> 3 | F181: {=SUMPRODUCT(ISNUMBER(SEARCH(CommunalDict, D181))*1)} -> 11 | G181: {=SUMPRODUCT(ISNUMBER(SEARCH(NeutralDict, D181))*1)} -> 16 | H181: =SUMPRODUCT(ISNUMBER(SEARCH(NegativeDict, D181))*1) -> 0 | I181: =IF(LEN(TRIM(D181))=0,0,LEN(TRIM(D181))-LEN(SUBSTITUTE(TRIM(D181)," ",""))+7) -> 170 | J181: =SUM( I181 / VLOOKUP(A181, BaseUP!A:H, 8, FALSE)*100) -> 106.25 | K181: =IF($C181="Agentic",SUM(E181/I181*100),SUM(F181/I181*100)) -> 6.4705882 | L181: [] | M181: =IF(AND(J181<=112, J181>=90, K181<=10.5, K181>=4.5, L181="[]"), "Pass", "Fail") -> Pass

Sheet BaseUP
A1: Base_CV_ID | B1: Field | C1: Cover_Letter | D1: Agentic_Count | E1: Communal_Count | F1: Neutral_Count | G1: Negative_Count | H1: Total_Words
A2: 1 | B2: Sales / Business Development | C2: Dear Hiring Manager, I am writing to submit my application for the Sales Executive position at your company. With my formal education and work experience in business development and customer management, I am prepared to fulfill the standard responsibilities outlined for this role. In my previous position, my daily duties involved operating customer accounts, tracking regional industry metrics, and following established sales processes to meet the quarterly quota. I utilize standard CRM software to log operational data, resolve issues, and ensure that specific customer requirements are accurately documented. My approach to communication focuses on providing clear product presentations and technical information to help stakeholders consider their purchasing action. Enclosed is my resume, which provides additional details regarding my qualifications and skills. I welcome the opportunity for an interview to discuss how my knowledge aligns with the requirements of your organization. Thank you for your time and consideration. Regards, [Your Name] | D2: 2 | E2: 0 | F2: 28 | G2: 0 | H2: 144
A3: 2 | B3: Sales / Business Development | C3: Dear Hiring Manager, Please accept this application for the Business Development Specialist role currently open within your organization. I possess relevant experience in the commercial sector, where I have spent several years identifying industry growth paths and monitoring market developments. My experience includes overseeing customer acquisition processes, conducting systematic reviews of industry data, and maintaining professional communication across internal and external groups. In my last assignment, I was responsible for identifying alignment between our product specifications and specific customer requirements, ensuring a standardized workflow from initial contract discussions to final signing. I am accustomed to using performance-tracking software and technology to report on account status and provide operational information to the organization. I have attached my resume for your comprehensive review. I look forward to the possibility of a follow-up contact to schedule a discussion regarding my qualifications for this position. Regards, [Your Name] | D3: 3 | E3: 0 | F3: 22 | G3: 0 | H3: 139
A4: 3 | B4: Procurement / Sourcing / Supply Chain | C4: Dear Hiring Manager, I am writing to apply for the Procurement Officer position at your company. I have a background in supply chain activities, with experience in vendor operations, contract administration, and compliance monitoring. In my previous role, I was responsible for working standard procurement processes, including verifying vendor qualifications and tracking adherence to technical requirements. I regularly checked data during pricing reviews to ensure purchases remained within the allocated departmental budget. Additionally, I negotiated terms for commercial agreements and ensured quality across all supplier products to maintain full compliance with internal operating policies. My attached resume details my formal credentials and specific experience with enterprise resource planning software. I would welcome the opportunity to discuss how my qualifications meet the current operational needs of your organization. Thank you for your time and consideration. Regards, [Your Name] | D4: 2 | E4: 0 | F4: 20 | G4: 0 | H4: 131
A5: 4 | B5: Procurement / Sourcing / Supply Chain | C5: Dear Hiring Manager, This letter is in reference to the Logistics Coordinator role currently available within your organization. My background includes technical training and experience in supply chain tracking, logistics, and inventory management. My professional focus is on maintaining stable workflow processes. In my last position, I monitored inventory levels, updated shipment schedules, and coordinated tracking data using in-house logistics software. Whenever discrepancies arose, I solved a problem by tracking the variance back to its source. I worked with others from warehouse operations and transportation and ensure that physical stock levels aligned exactly with system requirements. My qualifications are outlined in detail in the attached resume. Please feel free to contact me via the information provided to schedule a discussion regarding this position. Thank you for your review and consideration. Regards, [Your Name] | D5: 1 | E5: 0 | F5: 20 | G5: 0 | H5: 127
A6: 5 | B6: Project Management / Programme Management | C6: Dear Hiring Manager, I am writing to express my interest in the Project Manager position at your company. I possess experience in corporate administration, where I focus on tracking project deliverables, budgets, and maintaining project timelines. Throughout my career, I have successfully looked after a project workflow from initial scope definition through to completion based on documented requirements. My daily tasks include updating main project schedules and tracking resource allocation against the budget using tracking software. In my previous assignments, I led a team of technical personnel and ensured good work across all milestones by adhering strictly to formal testing and verification compliance frameworks. My background includes specific certification in standard project methodologies. Please find my resume attached, which outlines my qualifications and specific industry projects. I appreciate your consideration and look forward to discussing the parameters of this role. Regards, [Your Name] | D6: 2 | E6: 1 | F6: 18 | G6: 0 | H6: 138
A7: 6 | B7: Project Management / Programme Management | C7: Dear Hiring Manager, Please accept my application for the Programme Coordinator role within your organization. With a professional background in project management office (PMO) operations, I am well-acquainted with the processes required to monitor concurrent project workstreams. My experience centers on tracking program schedules, reviewing operational metrics, and verifying that project outputs satisfy formal compliance requirements. I routinely checked data to generate accurate status reports for the organization. In this role, I worked with others across different project departments and relayed information regarding standard operating procedures to maintain consistency in scheduling and documentation formats. My resume is attached for your comprehensive review. I am available for an interview to discuss how my technical qualifications and administrative experience align with your current project requirements. Thank you for your consideration. Regards, [Your Name] | D7: 2 | E7: 0 | F7: 19 | G7: 0 | H7: 125
A8: 7 | B8: Sales / Business Development | C8: Dear Hiring Manager, I am writing to submit my application for the Sales and Business Development position at [Company] in [Location]. My professional background includes sales operations. During this period, I managed accounts and processed new business inquiries. I maintained records of client interactions and performed outreach activities to generate interest in products. My technical abilities include the use of customer relationship management software and standard office programs. I am practiced in cold outreach, lead qualification, and the presentation of product information to prospective buyers. I adhere to standard sales procedures and report on metrics as requested. I am available for an interview to discuss how my background aligns with the requirements of this role. Please contact me at your convenience to arrange a meeting. Regards, [Your Name] | D8: 3 | E8: 2 | F8: 13 | G8: 0 | H8: =IF(LEN(TRIM(C8))=0,0,LEN(TRIM(C8))-LEN(SUBSTITUTE(TRIM(C8)," ",""))+7) -> 128
A9: 8 | B9: Sales / Business Development | C9: Dear Hiring Manager, I am writing to apply for the Sales and Business Development position at [Company] in [Location]. This letter serves to express my interest in the vacancy as advertised. My background includes sales operations and client relations. During this time, I managed account portfolios and processed client inquiries. I maintained records of client interactions and provided updates to management regarding status reports. My daily tasks included cold calling, lead identification, and the arrangement of meetings. I utilized software to track engagement metrics and prepared documentation for contract negotiations. I am proficient in standard office software and communication tools. I am available for an interview to discuss this role. Please contact me via the information provided on my resume to arrange a meeting. Regards, [Your Name] | D9: 2 | E9: 3 | F9: 11 | G9: 0 | H9: =IF(LEN(TRIM(C9))=0,0,LEN(TRIM(C9))-LEN(SUBSTITUTE(TRIM(C9)," ",""))+7) -> 127
A10: 9 | B10: Sales / Business Development | C10: Dear Hiring Manager, I am writing to apply for the Sales and Business Development position at [Company] in [Location]. This letter serves as a formal expression of interest in the vacancy. My professional background includes sales operations. During this period, I managed accounts, engaged with prospective clients, and maintained records of business interactions. I performed tasks related to market research and client outreach to facilitate business operations. My technical skills include the use of customer relationship management software and data entry systems. I am proficient in the use of office productivity software and communication tools. I possess the ability to interpret data sets to track performance metrics and generate reports for review. I am available for an interview to discuss this application. Please contact me via the information provided on my resume to arrange a meeting. Regards, [Your Name] | D10: 3 | E10: 3 | F10: 14 | G10: 0 | H10: =IF(LEN(TRIM(C10))=0,0,LEN(TRIM(C10))-LEN(SUBSTITUTE(TRIM(C10)," ",""))+7) -> 139
A11: 10 | B11: Sales / Business Development | C11: Dear Hiring Manager, I am writing to apply for the Sales and Business Development position at [Company] in [Location]. This letter expresses my interest in the vacancy as advertised. My professional background includes sales operations. During this period, I managed client accounts and processed business transactions. I held responsibility for maintaining records and communicating with prospective entities regarding service offerings. My technical skills include the use of customer relationship management software and data entry systems. I possess the ability to conduct cold outreach and present information to potential clients. I maintain standard office productivity tools to track progress and report metrics to management. I am available to discuss my qualifications for this position at your convenience. Please contact me via the information provided on my resume to arrange an interview. Regards, [Your Name] | D11: 1 | E11: 5 | F11: 13 | G11: 0 | H11: =IF(LEN(TRIM(C11))=0,0,LEN(TRIM(C11))-LEN(SUBSTITUTE(TRIM(C11)," ",""))+7) -> 133
A12: 11 | B12: Sales / Business Development | C12: Dear Hiring Manager, I am writing to express interest in the Sales position at [Company] located in [Location]. My application is submitted for your consideration regarding this opening. My professional history includes roles in sales and business development. In these positions, I managed accounts and processed transactions. I maintained records of client interactions and provided information about products. These responsibilities required consistent adherence to established operational procedures. My experience includes prospecting for new contacts and presenting information to potential clients. I am familiar with the use of standard software for tracking activity and maintaining contact databases. I communicate facts regarding product features and pricing structures to facilitate business exchanges. I am available for an interview to discuss how my background aligns with the requirements of [Company]. Please contact me at your convenience to arrange a time. Thank you for your time and attention to this application. Regards, [Your Name] | D12: 2 | E12: 3 | F12: 15 | G12: 0 | H12: =IF(LEN(TRIM(C12))=0,0,LEN(TRIM(C12))-LEN(SUBSTITUTE(TRIM(C12)," ",""))+7) -> 149
A13: 12 | B13: Sales / Business Development | C13: Dear Hiring Manager, I am writing to express interest in the Sales / Business Development position at [Company] in [Location]. This letter serves as my formal application for the role. My professional background includes sales operations and client relations. During this time, I managed account portfolios and processed new client acquisitions. I have maintained records of customer interactions and processed contracts within the parameters of established organizational procedures. My core competencies include data entry, cold outreach, and the management of customer relationship databases. I am proficient in the use of standard office software to track activity and generate reports. These tasks are performed according to the protocols set by the organization to ensure accuracy in all records. I am available for an interview at your convenience to discuss how my background aligns with the requirements of this position. Thank you for your consideration of this application. Regards, [Your Name] | D13: 2 | E13: 3 | F13: 14 | G13: 0 | H13: =IF(LEN(TRIM(C13))=0,0,LEN(TRIM(C13))-LEN(SUBSTITUTE(TRIM(C13)," ",""))+7) -> 149
A14: 13 | B14: Sales / Business Development | C14: Dear Hiring Manager, I am writing to submit my application for the Sales and Business Development position at [Company] located in [Location]. My background aligns with the requirements stated in the job description. My professional history includes sales operations. During this period, I managed client accounts and processed business transactions. I held responsibility for maintaining records, communicating with prospects, and facilitating the progress of sales cycles. I possess proficiency in customer relationship management software and data entry. My technical skills include the use of office productivity tools and the analysis of sales metrics. I maintain accurate documentation and communicate information to internal departments. I am available for an interview to discuss how my qualifications align with the needs of [Company]. Please contact me at your convenience to arrange a meeting. Regards, [Your Name] | D14: 1 | E14: 4 | F14: 13 | G14: 0 | H14: =IF(LEN(TRIM(C14))=0,0,LEN(TRIM(C14))-LEN(SUBSTITUTE(TRIM(C14)," ",""))+7) -> 133
